<?xml version="1.0" encoding="utf-8"?>
<!-- =================================================================================== -->
<!-- |    This document was autogenerated by xacro from ur5_robot.urdf.xacro           | -->
<!-- |    EDITING THIS FILE BY HAND IS NOT RECOMMENDED                                 | -->
<!-- =================================================================================== -->
<robot name="combined">
  <!--robots pose-->
  <link name="world"/>

  <joint name="sawyer_pose" type="fixed">
    <origin rpy="0 0 0" xyz="0. 0. 0.11"/><!--sawyer base-->
    <parent link="world"/>
    <child link="sawyer_pedestal"/>
  </joint>

  <joint name="abb_pose" type="fixed">
    <parent link="world"/>
    <child link="abb_pedestal"/>
    <origin rpy="0.0 0.0 0.0" xyz="0 1.2 0.0"/><!--abb pedestal-->
  </joint>


  

  <material name="black">
    <color rgba="0 0 0 1"/>
  </material>
  <material name="darkgray">
    <color rgba=".2 .2 .2 1"/>
  </material>
  <material name="darkred">
    <color rgba=".5 .1 .1 1"/>
  </material>
  <material name="sawyer_red">
    <color rgba=".5 .1 .1 1"/>
  </material>
  <material name="sawyer_gray">
    <color rgba="0.75294 0.75294 0.75294 1"/>
  </material>
  <link name="sawyer_pedestal"/>
  <link name="torso">
    <visual>
      <origin rpy="0 0 0" xyz="0 0 0"/>
      <geometry>
        <box size="0.001 0.001 0.001"/>
      </geometry>
      <material name="darkgray">
        <color rgba=".2 .2 .2 1"/>
      </material>
    </visual>
    <inertial>
      <origin rpy="0 0 0" xyz="0.000000 0.000000 0.000000"/>
      <mass value="0.0001"/>
      <inertia ixx="1e-08" ixy="0" ixz="0" iyy="1e-08" iyz="0" izz="1e-08"/>
    </inertial>
  </link>
  <link name="pedestal">
    <visual>
      <origin rpy="1.57079632679 0 -1.57079632679" xyz="0.26 0.345 -0.91488"/>
      <geometry>
        <mesh filename="model://sawyer/meshes/sawyer_pv/pedestal.DAE"/>
      </geometry>
      <material name="darkgray"/>
    </visual>
 <!--    <collision>
      <origin rpy="0 0 0" xyz="-0.02 0 -0.29"/>
      <geometry>
        <cylinder length="0.62" radius="0.18"/>
      </geometry>
    </collision> -->
    <inertial>
      <origin rpy="0 0 0" xyz="0 0 -0.5"/>
      <mass value="60.86397744"/>
      <inertia ixx="5.0635929" ixy="0.00103417" ixz="0.80199628" iyy="6.08689388" iyz="0.00105311" izz="4.96191932"/>
    </inertial>
  </link>
  <link name="controller_box">
   <!--  <collision>
      <origin rpy="0 0 0" xyz="-0.325 0 -0.38"/>
      <geometry>
        <box size="0.22 0.4 0.53"/>
      </geometry>
    </collision> -->
  </link>
  <joint name="controller_box_fixed" type="fixed">
    <origin rpy="0 0 0" xyz="0.0 0.0 0.0"/>
    <parent link="sawyer_pedestal"/>
    <child link="controller_box"/>
  </joint>
  <link name="pedestal_feet">
    <collision>
      <origin rpy="0 0 0" xyz="-0.1225 0 -0.758"/>
      <geometry>
        <box size="0.77 0.7 0.31"/>
      </geometry>
    </collision>
  </link>
  <joint name="pedestal_feet_fixed" type="fixed">
    <origin rpy="0 0 0" xyz="0.0 0.0 0.0"/>
    <parent link="sawyer_pedestal"/>
    <child link="pedestal_feet"/>
  </joint>
  <joint name="pedestal_fixed" type="fixed">
    <origin rpy="0 0 0" xyz="0.0 0.0 0.0"/>
    <parent link="sawyer_pedestal"/>
    <child link="pedestal"/>
  </joint>
  <joint name="right_arm_mount" type="fixed">
    <origin rpy="0 0 0" xyz="0.0 0.0 0.0"/>
    <parent link="sawyer_pedestal"/>
    <child link="right_arm_base_link"/>
  </joint>
  <joint name="torso_t0" type="fixed">
    <origin rpy="0 0 0" xyz="0 0 0"/>
    <parent link="sawyer_pedestal"/>
    <child link="torso"/>
  </joint>
  <link name="right_arm_base_link">
    <inertial>
      <origin rpy="0 0 0" xyz="-0.0006241 -2.8025E-05 0.065404"/>
      <mass value="2.0687"/>
      <inertia ixx="0.0067599" ixy="-4.2024E-05" ixz="-6.1904E-07" iyy="0.0067877" iyz="1.5888E-05" izz="0.0074031"/>
    </inertial>
    <visual>
      <origin rpy="0 0 0" xyz="0 0 0"/>
      <geometry>
        <mesh filename="model://sawyer/meshes/sawyer_pv/base.DAE"/>
      </geometry>
      <material name="sawyer_red"/>
    </visual>
    <!-- <collision>
      <origin rpy="0 0 0" xyz="0 0 0.12"/>
      <geometry>
        <cylinder length="0.24" radius="0.08"/>
      </geometry>
    </collision> -->
  </link>
  <link name="right_l0">
    <inertial>
      <origin rpy="0 0 0" xyz="0.024366 0.010969 0.14363"/>
      <mass value="5.3213"/>
      <inertia ixx="0.053314" ixy="0.0047093" ixz="0.011734" iyy="0.057902" iyz="0.0080179" izz="0.023659"/>
    </inertial>
    <visual>
      <origin rpy="0 0 0" xyz="0 0 0"/>
      <geometry>
        <mesh filename="model://sawyer/meshes/sawyer_mp3/l0.DAE"/>
      </geometry>
      <material name="sawyer_red"/>
    </visual>
    <collision>
      <origin rpy="0 0 0" xyz="0.08 0 0.23"/>
      <geometry>
        <sphere radius="0.07"/>
      </geometry>
    </collision>
  </link>
  <joint name="right_j0" type="revolute">
    <origin rpy="0 0 0" xyz="0 0 0.08"/>
    <parent link="right_arm_base_link"/>
    <child link="right_l0"/>
    <axis xyz="0 0 1"/>
    <limit effort="80.0" lower="-3.0503" upper="3.0503" velocity="1.74"/>
  </joint>
  <link name="head">
    <inertial>
      <origin rpy="0 0 0" xyz="0.0053207 -2.6549E-05 0.1021"/>
      <mass value="1.5795"/>
      <inertia ixx="0.011833" ixy="-4.4669E-06" ixz="4.9425E-05" iyy="0.0082709" iyz="4.2124E-07" izz="0.0049661"/>
    </inertial>
    <visual>
      <origin rpy="0 0 0" xyz="0 0 0"/>
      <geometry>
        <mesh filename="model://sawyer/meshes/sawyer_pv/head.DAE"/>
      </geometry>
      <material name="sawyer_red"/>
    </visual>
    <collision>
      <origin rpy="0 0 0" xyz="0 0 0.08"/>
      <geometry>
        <sphere radius="0.18"/>
      </geometry>
    </collision>
  </link>
  <joint name="head_pan" type="revolute">
    <origin rpy="0 0 0" xyz="0 0 0.2965"/>
    <parent link="right_l0"/>
    <child link="head"/>
    <axis xyz="0 0 1"/>
    <limit effort="8" lower="-5.0952" upper="0.9064" velocity="1.8"/>
  </joint>
  <link name="right_torso_itb">
    <inertial>
      <origin rpy="0 0 0" xyz="0.000000 0.000000 0.000000"/>
      <mass value="0.0001"/>
      <inertia ixx="1e-08" ixy="0" ixz="0" iyy="1e-08" iyz="0" izz="1e-08"/>
    </inertial>
  </link>
  <joint name="right_torso_itb" type="fixed">
    <origin rpy="0 -1.57079632679 0" xyz="-.055 0 .22"/>
    <parent link="right_l0"/>
    <child link="right_torso_itb"/>
    <axis xyz="0 0 1"/>
  </joint>
  <link name="right_l1">
    <inertial>
      <origin rpy="0 0 0" xyz="-0.0030849 -0.026811 0.092521"/>
      <mass value="4.505"/>
      <inertia ixx="0.022398" ixy="-0.00023986" ixz="-0.00029362" iyy="0.014613" iyz="-0.0060875" izz="0.017295"/>
    </inertial>
    <visual>
      <origin rpy="0 0 0" xyz="0 0 0"/>
      <geometry>
        <mesh filename="model://sawyer/meshes/sawyer_mp3/l1.DAE"/>
      </geometry>
      <material name="sawyer_red"/>
    </visual>
    <collision>
      <origin rpy="0 0 0" xyz="0 0 0.1225"/>
      <geometry>
        <sphere radius="0.07"/>
      </geometry>
    </collision>
  </link>
  <joint name="right_j1" type="revolute">
    <origin rpy="-1.57079632679 1.57079632679 0" xyz="0.081 0.05 0.237"/>
    <parent link="right_l0"/>
    <child link="right_l1"/>
    <axis xyz="0 0 1"/>
    <limit effort="80.0" lower="-3.8095" upper="2.2736" velocity="1.328"/>
  </joint>
  <link name="right_l2">
    <inertial>
      <origin rpy="0 0 0" xyz="-0.00016044 -0.014967 0.13582"/>
      <mass value="1.745"/>
      <inertia ixx="0.025506" ixy="4.4101E-06" ixz="1.4955E-05" iyy="0.0253" iyz="-0.0033204" izz="0.0034179"/>
    </inertial>
    <visual>
      <origin rpy="0 0 0" xyz="0 0 0"/>
      <geometry>
        <mesh filename="model://sawyer/meshes/sawyer_pv/l2.DAE"/>
      </geometry>
      <material name="sawyer_red"/>
    </visual>
    <collision>
      <origin rpy="0 0 0" xyz="0 0 0.08"/>
      <geometry>
        <cylinder length="0.34" radius="0.06"/>
      </geometry>
    </collision>
  </link>
  <joint name="right_j2" type="revolute">
    <origin rpy="1.57079632679 0 0" xyz="0 -0.14 0.1425"/>
    <parent link="right_l1"/>
    <child link="right_l2"/>
    <axis xyz="0 0 1"/>
    <limit effort="40.0" lower="-3.0426" upper="3.0426" velocity="1.957"/>
  </joint>
  <link name="right_l3">
    <inertial>
      <origin rpy="0 0 0" xyz="-0.0048135 -0.0281 -0.084154"/>
      <mass value="2.5097"/>
      <inertia ixx="0.01016" ixy="-9.7452E-06" ixz="0.00026624" iyy="0.0065685" iyz="0.0030316" izz="0.0069078"/>
    </inertial>
    <visual>
      <origin rpy="0 0 0" xyz="0 0 0"/>
      <geometry>
        <mesh filename="model://sawyer/meshes/sawyer_pv/l3.DAE"/>
      </geometry>
      <material name="sawyer_red"/>
    </visual>
    <collision>
      <origin rpy="0 0 0" xyz="0 -0.01 -0.12"/>
      <geometry>
        <sphere radius="0.06"/>
      </geometry>
    </collision>
  </link>
  <joint name="right_j3" type="revolute">
    <origin rpy="-1.57079632679 0 0" xyz="0 -0.042 0.26"/>
    <parent link="right_l2"/>
    <child link="right_l3"/>
    <axis xyz="0 0 1"/>
    <limit effort="40.0" lower="-3.0439" upper="3.0439" velocity="1.957"/>
  </joint>
  <link name="right_l4">
    <inertial>
      <origin rpy="0 0 0" xyz="-0.0018844 0.0069001 0.1341"/>
      <mass value="1.1136"/>
      <inertia ixx="0.013557" ixy="1.8109E-05" ixz="0.00013523" iyy="0.013555" iyz="0.0010561" izz="0.0013658"/>
    </inertial>
    <visual>
      <origin rpy="0 0 0" xyz="0 0 0"/>
      <geometry>
        <mesh filename="model://sawyer/meshes/sawyer_pv/l4.DAE"/>
      </geometry>
      <material name="sawyer_red"/>
    </visual>
    <collision>
      <origin rpy="0 0 0" xyz="0 0 0.11"/>
      <geometry>
        <cylinder length="0.30" radius="0.045"/>
      </geometry>
    </collision>
  </link>
  <joint name="right_j4" type="revolute">
    <origin rpy="1.57079632679 0 0" xyz="0 -0.125 -0.1265"/>
    <parent link="right_l3"/>
    <child link="right_l4"/>
    <axis xyz="0 0 1"/>
    <limit effort="9.0" lower="-2.9761" upper="2.9761" velocity="3.485"/>
  </joint>
  <link name="right_arm_itb">
    <inertial>
      <origin rpy="0 0 0" xyz="0.000000 0.000000 0.000000"/>
      <mass value="0.0001"/>
      <inertia ixx="1e-08" ixy="0" ixz="0" iyy="1e-08" iyz="0" izz="1e-08"/>
    </inertial>
  </link>
  <joint name="right_arm_itb" type="fixed">
    <origin rpy="0 -1.57079632679 0" xyz="-.055 0 .075"/>
    <parent link="right_l4"/>
    <child link="right_arm_itb"/>
    <axis xyz="0 0 1"/>
  </joint>
  <link name="right_l5">
    <inertial>
      <origin rpy="0 0 0" xyz="0.0061133 -0.023697 0.076416"/>
      <mass value="1.5625"/>
      <inertia ixx="0.0047328" ixy="0.00011526" ixz="4.6269E-05" iyy="0.0029676" iyz="-0.0011557" izz="0.0031762"/>
    </inertial>
    <visual>
      <origin rpy="0 0 0" xyz="0 0 0"/>
      <geometry>
        <mesh filename="model://sawyer/meshes/sawyer_pv/l5.DAE"/>
      </geometry>
      <material name="sawyer_red"/>
    </visual>
    <collision>
      <origin rpy="0 0 0" xyz="0 0 0.1"/>
      <geometry>
        <sphere radius="0.06"/>
      </geometry>
    </collision>
  </link>
  <joint name="right_j5" type="revolute">
    <origin rpy="-1.57079632679 0 0" xyz="0 0.031 0.275"/>
    <parent link="right_l4"/>
    <child link="right_l5"/>
    <axis xyz="0 0 1"/>
    <limit effort="9.0" lower="-2.9761" upper="2.9761" velocity="3.485"/>
  </joint>
  <link name="right_hand_camera"/>
  <joint name="right_hand_camera" type="fixed">
    <origin rpy="0 1.57079632679 0" xyz="0.039552 -0.033 0.0695"/>
    <parent link="right_l5"/>
    <child link="right_hand_camera"/>
    <axis xyz="0 0 0"/>
  </joint>
  <link name="right_wrist"/>
  <joint name="right_wrist" type="fixed">
    <origin rpy="1.57079632679 0 0" xyz="0 0 0.10541"/>
    <parent link="right_l5"/>
    <child link="right_wrist"/>
    <axis xyz="0 0 0"/>
  </joint>
  <link name="right_l6">
    <inertial>
      <origin rpy="0 0 0" xyz="-8.0726E-06 0.0085838 -0.0049566"/>
      <mass value="0.3292"/>
      <inertia ixx="0.00031105" ixy="1.4771E-06" ixz="-3.7074E-07" iyy="0.00021549" iyz="-8.4533E-06" izz="0.00035976"/>
    </inertial>
    <visual>
      <origin rpy="0 0 0" xyz="0 0 0"/>
      <geometry>
        <mesh filename="model://sawyer/meshes/sawyer_mp1/l6.DAE"/>
      </geometry>
      <material name="sawyer_red"/>
    </visual>
    <collision>
      <origin rpy="0 0 0" xyz="0 0.015 -0.01"/>
      <geometry>
        <cylinder length="0.05" radius="0.055"/>
      </geometry>
    </collision>
  </link>
  <joint name="right_j6" type="revolute">
    <origin rpy="-1.57079632679 -0.17453 3.1416" xyz="0 -0.11 0.1053"/>
    <parent link="right_l5"/>
    <child link="right_l6"/>
    <axis xyz="0 0 1"/>
    <limit effort="9.0" lower="-4.7124" upper="4.7124" velocity="4.545"/>
  </joint>
  <link name="right_hand">
    <collision>
      <origin rpy="0 0 0" xyz="0 0 0.02"/>
      <geometry>
        <cylinder length="0.03" radius="0.035"/>
      </geometry>
    </collision>
    <inertial>
      <origin rpy="0 0 0" xyz="1.0E-08 1.0E-08 1.0E-08"/>
      <mass value="1.0E-08"/>
      <inertia ixx="1.0E-08" ixy="1.0E-08" ixz="1.0E-08" iyy="1.0E-08" iyz="1.0E-08" izz="1.0E-08"/>
    </inertial>
  </link>
  <joint name="right_hand" type="fixed">
    <origin rpy="0 0 1.570796" xyz="0 0 0.0245"/>
    <axis xyz="0 0 1"/>
    <parent link="right_l6"/>
    <child link="right_hand"/>
  </joint>
  <link name="right_l1_2">
    <inertial>
      <origin rpy="0 0 0" xyz="1.0E-08 1.0E-08 1.0E-08"/>
      <mass value="1.0E-08"/>
      <inertia ixx="1.0E-08" ixy="1.0E-08" ixz="1.0E-08" iyy="1.0E-08" iyz="1.0E-08" izz="1.0E-08"/>
    </inertial>
    <collision>
      <origin rpy="0 0 0" xyz="0 0 0.035"/>
      <geometry>
        <cylinder length="0.14" radius="0.07"/>
      </geometry>
    </collision>
  </link>
  <joint name="right_j1_2" type="fixed">
    <origin rpy="0 0 0" xyz="0 0 0"/>
    <parent link="right_l1"/>
    <child link="right_l1_2"/>
    <axis xyz="0 0 1"/>
  </joint>
  <link name="right_l2_2">
    <inertial>
      <origin rpy="0 0 0" xyz="1.0E-08 1.0E-08 1.0E-08"/>
      <mass value="1.0E-08"/>
      <inertia ixx="1.0E-08" ixy="1.0E-08" ixz="1.0E-08" iyy="1.0E-08" iyz="1.0E-08" izz="1.0E-08"/>
    </inertial>
    <collision>
      <origin rpy="0 0 0" xyz="0 0 0.26"/>
      <geometry>
        <sphere radius="0.06"/>
      </geometry>
    </collision>
  </link>
  <joint name="right_j2_2" type="fixed">
    <origin rpy="0 0 0" xyz="0 0 0"/>
    <parent link="right_l2"/>
    <child link="right_l2_2"/>
    <axis xyz="0 0 1"/>
  </joint>
  <link name="right_l4_2">
    <inertial>
      <origin rpy="0 0 0" xyz="1.0E-08 1.0E-08 1.0E-08"/>
      <mass value="1.0E-08"/>
      <inertia ixx="1.0E-08" ixy="1.0E-08" ixz="1.0E-08" iyy="1.0E-08" iyz="1.0E-08" izz="1.0E-08"/>
    </inertial>
    <collision>
      <origin rpy="0 0 0" xyz="0 0.01 0.26"/>
      <geometry>
        <sphere radius="0.06"/>
      </geometry>
    </collision>
  </link>
  <joint name="right_j4_2" type="fixed">
    <origin rpy="0 0 0" xyz="0 0 0"/>
    <parent link="right_l4"/>
    <child link="right_l4_2"/>
    <axis xyz="0 0 1"/>
  </joint>
  <link name="screen">
    <visual>
      <origin rpy="0 0 0" xyz="0 0 0"/>
      <geometry>
        <box size="0.24 0.14 0.002"/>
      </geometry>
      <material name="darkgray"/>
    </visual>
    <collision>
      <origin rpy="0 0 0" xyz="0 0 0"/>
      <geometry>
        <sphere radius="0.001"/>
      </geometry>
    </collision>
    <inertial>
      <origin rpy="0 0 0" xyz="0 0 0"/>
      <mass value="0.0001"/>
      <inertia ixx="1e-08" ixy="0" ixz="0" iyy="1e-08" iyz="0" izz="1e-08"/>
    </inertial>
  </link>
  <joint name="display_joint" type="fixed">
    <origin rpy="1.57079632679 0 1.57079632679" xyz="0.03 0.0 0.105"/>
    <parent link="head"/>
    <child link="screen"/>
  </joint>
  <link name="head_camera"/>
  <joint name="head_camera" type="fixed">
    <origin rpy="-2.1293 0 -1.57079632679" xyz="0.0228027 0 0.216572"/>
    <parent link="head"/>
    <child link="head_camera"/>
    <axis xyz="0 0 0"/>
  </joint>

  <!--ABB part-->
  <joint name="ABB1200_joint_1" type="revolute">
    <parent link="ABB1200_base_link"/>
    <child link="ABB1200_link_1"/>
    <origin rpy="0 0 0" xyz="0     0     0.3991"/>
    <axis xyz="0 0 1"/>
    <limit effort="1000.0" lower="-2.967" upper="2.967" velocity="5.027"/>
  </joint>
  <joint name="ABB1200_joint_2" type="revolute">
    <parent link="ABB1200_link_1"/>
    <child link="ABB1200_link_2"/>
    <origin rpy="0 0 0" xyz="0 0 0"/>
    <axis xyz="0 1 0"/>
    <limit effort="1000.0" lower="-1.745" upper="2.269" velocity="4.189"/>
  </joint>
  <joint name="ABB1200_joint_3" type="revolute">
    <parent link="ABB1200_link_2"/>
    <child link="ABB1200_link_3"/>
    <origin rpy="0 0 0" xyz="0    0    0.448"/>
    <axis xyz="0 1 0"/>
    <limit effort="1000.0" lower="-3.491" upper="1.222" velocity="5.236"/>
  </joint>
  <joint name="ABB1200_joint_4" type="revolute">
    <parent link="ABB1200_link_3"/>
    <child link="ABB1200_link_4"/>
    <origin rpy="0 0 0" xyz="0    0    0.042"/>
    <axis xyz="1 0 0"/>
    <limit effort="1000.0" lower="-4.712" upper="4.712" velocity="6.981"/>
  </joint>
  <joint name="ABB1200_joint_5" type="revolute">
    <parent link="ABB1200_link_4"/>
    <child link="ABB1200_link_5"/>
    <origin rpy="0 0 0" xyz="0.451 0    0"/>
    <axis xyz="0 1 0"/>
    <limit effort="1000.0" lower="-2.269" upper="2.269" velocity="7.069"/>
  </joint>
  <joint name="ABB1200_joint_6" type="revolute">
    <parent link="ABB1200_link_5"/>
    <child link="ABB1200_link_6"/>
    <origin rpy="0 0 0" xyz="0.082 0    0"/>
    <axis xyz="1 0 0"/>
    <limit effort="1000.0" lower="-6.283" upper="6.283" velocity="10.472"/>
  </joint>
  <joint name="abb_pedestal_JOINT_0" type="fixed">
    <parent link="abb_pedestal"/>
    <child link="ABB1200_base_link"/>
    <origin rpy="0 0 0" xyz="0 0 0"/>
    <axis xyz="0 0 0"/>
    <limit effort="0" lower="0" upper="0" velocity="0"/>
  </joint>
  <link name="ABB1200_base_link">
    <inertial>
      <mass value="13.7742"/>
      <origin rpy="0 0 0" xyz="-0.02898  0.00059  0.11273"/>
      <inertia ixx="0.101998" ixy="0.000495482" ixz="0.000311158" iyy="0.13969" iyz="-0.000245375" izz="0.130433"/>
    </inertial>
    <!-- <collision name="ABB1200_base_link_fixed_joint_lump__collision_collision">
      <origin rpy="0 0 0" xyz="0 0 0"/>
      <geometry>
        <mesh filename="model://abb/meshes/collision/base_link.stl" scale="1 1 1"/>
      </geometry>
    </collision> -->
    <visual name="ABB1200_base_link_fixed_joint_lump__visual_visual">
      <origin rpy="0 0 0" xyz="0 0 0"/>
      <geometry>
        <mesh filename="model://abb/meshes/visual/base_link.dae" scale="1 1 1"/>
      </geometry>
    </visual>
  </link>
  <link name="abb_pedestal">
    <inertial>
      <mass value="1"/>
      <origin rpy="0 0 0" xyz="0 0 0"/>
      <inertia ixx="0.145833" ixy="0" ixz="0" iyy="0.145833" iyz="0" izz="0.125"/>
    </inertial>
    <visual name="ABB1200_visual">
      <origin rpy="0 0 0" xyz="0   0  -0.5"/>
      <geometry>
        <cylinder length="1.0" radius="0.2"/>
      </geometry>
    </visual>
  </link>
  <link name="ABB1200_link_1">
    <inertial>
      <mass value="11.8419"/>
      <origin rpy="0 0 0" xyz="0.00087 -0.00063 -0.06288"/>
      <inertia ixx="0.11194" ixy="-4.54988e-05" ixz="0.000280961" iyy="0.0915159" iyz="-0.000109905" izz="0.0876456"/>
    </inertial>
    <collision name="ABB1200_link_1_fixed_joint_lump__collision_collision">
      <origin rpy="0 0 0" xyz="0 0 0"/>
      <geometry>
        <mesh filename="model://abb/meshes/collision/link_1.stl" scale="1 1 1"/>
      </geometry>
    </collision>
    <visual name="ABB1200_link_1_fixed_joint_lump__visual_visual">
      <origin rpy="0 0 0" xyz="0 0 0"/>
      <geometry>
        <mesh filename="model://abb/meshes/visual/link_1.dae" scale="1 1 1"/>
      </geometry>
    </visual>
  </link>
  <link name="ABB1200_link_2">
    <inertial>
      <mass value="17.5394"/>
      <origin rpy="0 0 0" xyz="-0.00092 -0.00049  0.25005"/>
      <inertia ixx="0.493558" ixy="1.32136e-05" ixz="0.000209024" iyy="0.462939" iyz="-0.00179901" izz="0.0894214"/>
    </inertial>
    <collision name="ABB1200_link_2_fixed_joint_lump__collision_collision">
      <origin rpy="0 0 0" xyz="0 0 0"/>
      <geometry>
        <mesh filename="model://abb/meshes/collision/link_2.stl" scale="1 1 1"/>
      </geometry>
    </collision>
    <visual name="ABB1200_link_2_fixed_joint_lump__visual_visual">
      <origin rpy="0 0 0" xyz="0 0 0"/>
      <geometry>
        <mesh filename="model://abb/meshes/visual/link_2.dae" scale="1 1 1"/>
      </geometry>
    </visual>
  </link>
  <link name="ABB1200_link_3">
    <inertial>
      <mass value="7.46365"/>
      <origin rpy="0 0 0" xyz="0.09958 0.00114 0.03233"/>
      <inertia ixx="0.0252424" ixy="0.000142737" ixz="-0.00565542" iyy="0.0906438" iyz="0.000142213" izz="0.0825079"/>
    </inertial>
    <collision name="ABB1200_link_3_fixed_joint_lump__collision_collision">
      <origin rpy="0 0 0" xyz="0 0 0"/>
      <geometry>
        <mesh filename="model://abb/meshes/collision/link_3.stl" scale="1 1 1"/>
      </geometry>
    </collision>
    <visual name="ABB1200_link_3_fixed_joint_lump__visual_visual">
      <origin rpy="0 0 0" xyz="0 0 0"/>
      <geometry>
        <mesh filename="model://abb/meshes/visual/link_3.dae" scale="1 1 1"/>
      </geometry>
    </visual>
  </link>
  <link name="ABB1200_link_4">
    <inertial>
      <mass value="2.74436"/>
      <origin rpy="0 0 0" xyz="0.38167 0.00126 0.00516"/>
      <inertia ixx="0.00573099" ixy="-0.000131119" ixz="0.000380232" iyy="0.0118352" iyz="-2.26565e-05" izz="0.0114428"/>
    </inertial>
    <collision name="ABB1200_link_4_fixed_joint_lump__collision_collision">
      <origin rpy="0 0 0" xyz="0 0 0"/>
      <geometry>
        <mesh filename="model://abb/meshes/collision/link_4.stl" scale="1 1 1"/>
      </geometry>
    </collision>
    <visual name="ABB1200_link_4_fixed_joint_lump__visual_visual">
      <origin rpy="0 0 0" xyz="0 0 0"/>
      <geometry>
        <mesh filename="model://abb/meshes/visual/link_4.dae" scale="1 1 1"/>
      </geometry>
    </visual>
  </link>
  <link name="ABB1200_link_5">
    <inertial>
      <mass value="0.62953"/>
      <origin rpy="0 0 0" xyz="0.01119 -0.00105  0.0001"/>
      <inertia ixx="0.000502815" ixy="-1.03173e-05" ixz="-8.74347e-08" iyy="0.00108856" iyz="2.07657e-07" izz="0.000918873"/>
    </inertial>
    <collision name="ABB1200_link_5_fixed_joint_lump__collision_collision">
      <origin rpy="0 0 0" xyz="0 0 0"/>
      <geometry>
        <mesh filename="model://abb/meshes/collision/link_5.stl" scale="1 1 1"/>
      </geometry>
    </collision>
    <visual name="ABB1200_link_5_fixed_joint_lump__visual_visual">
      <origin rpy="0 0 0" xyz="0 0 0"/>
      <geometry>
        <mesh filename="model://abb/meshes/visual/link_5.dae" scale="1 1 1"/>
      </geometry>
    </visual>
  </link>
  <link name="ABB1200_link_6">
    <inertial>
      <mass value="0.137"/>
      <origin rpy="0 0 0" xyz="-0.00706 -0.00017  0"/>
      <inertia ixx="0.001" ixy="0" ixz="0" iyy="0.001" iyz="0" izz="0.001"/>
    </inertial>
    <collision name="ABB1200_link_6_fixed_joint_lump__collision_collision">
      <origin rpy="0 0 0" xyz="0 0 0"/>
      <geometry>
        <mesh filename="model://abb/meshes/collision/link_6.stl" scale="1 1 1"/>
      </geometry>
    </collision>
    <visual name="ABB1200_link_6_fixed_joint_lump__visual_visual">
      <origin rpy="0 0 0" xyz="0 0 0"/>
      <geometry>
        <mesh filename="model://abb/meshes/visual/link_6.dae" scale="1 1 1"/>
      </geometry>
    </visual>
  </link>


</robot>
